<?xml version="1.0" ?>
<robot name="larcc" version="1.0">
  <link name="world"/>
  <material name="Yellow">
    <color rgba="1.0 1.0 0.0 1.0"/>
  </material>
  <material name="Orange">
    <color rgba="1.0 0.4 0.0 1.0"/>
  </material>
  <material name="grey">
    <color rgba="0.7 0.7 0.7 1.0"/>
  </material>
  <material name="aluminum">
    <color rgba="0.5 0.5 0.5 1.0"/>
  </material>
  <material name="plastic">
    <color rgba="0.1 0.1 0.1 1.0"/>
  </material>
  <link name="gantry"/>
  <joint name="world_to_gantry" type="fixed">
    <origin xyz="0.0 0.0 0.0" rpy="0.0 0.0 0.0"/>
    <parent link="world"/>
    <child link="gantry"/>
  </joint>
  <link name="gantry_gantry">
    <inertial>
      <origin xyz="0.0 0.0 0.0" rpy="0.0 0.0 0.0"/>
      <mass value="1.0"/>
      <inertia ixx="1.0" ixy="0.0" ixz="0.0" iyy="1.0" iyz="0.0" izz="1.0"/>
    </inertial>
  </link>
  <gazebo reference="gantry_gantry">
    <material>Gazebo/Grey</material>
    <mu1>50.0</mu1>
    <mu2>50.0</mu2>
    <kp>1000000.0</kp>
    <kd>1.0</kd>
    <selfCollide>false</selfCollide>
  </gazebo>
  <joint name="gantry_to_gantry_gantry" type="fixed">
    <origin xyz="0.0 0.0 2.355" rpy="0.0 0.0 0.0"/>
    <parent link="gantry"/>
    <child link="gantry_gantry"/>
  </joint>
  <link name="leg1_gantry">
    <inertial>
      <origin xyz="0.0 0.0 1.1440000000000001" rpy="0.0 0.0 0.0"/>
      <mass value="1.0"/>
      <inertia ixx="0.1" ixy="0.0" ixz="0.0" iyy="0.1" iyz="0.0" izz="0.01"/>
    </inertial>
    <visual>
      <origin xyz="0.0 0.0 0.0" rpy="0.0 0.0 0.0"/>
      <geometry>
        <mesh filename="package://larcc_cell_description/meshes/minitec_90x90_2200.STL" scale="0.001 0.001 0.001"/>
      </geometry>
      <material name="grey"/>
    </visual>
    <collision>
      <origin xyz="0.045 0.045 1.1" rpy="0.0 0.0 0.0"/>
      <geometry>
        <box size="0.09 0.09 2.2"/>
      </geometry>
    </collision>
  </link>
  <gazebo reference="leg1_gantry">
    <material>Gazebo/Grey</material>
    <mu1>1000.0</mu1>
    <mu2>1000.0</mu2>
    <kp>10000000.0</kp>
    <kd>1.0</kd>
    <selfCollide>true</selfCollide>
  </gazebo>
  <joint name="gantry_to_leg1" type="fixed">
    <origin xyz="-2.09 1.39875 0.065" rpy="0.0 0.0 0.0"/>
    <parent link="gantry"/>
    <child link="leg1_gantry"/>
  </joint>
  <link name="leg2_gantry">
    <inertial>
      <origin xyz="0.0 0.0 1.1440000000000001" rpy="0.0 0.0 0.0"/>
      <mass value="1.0"/>
      <inertia ixx="0.1" ixy="0.0" ixz="0.0" iyy="0.1" iyz="0.0" izz="0.01"/>
    </inertial>
    <visual>
      <origin xyz="0.0 0.0 0.0" rpy="0.0 0.0 0.0"/>
      <geometry>
        <mesh filename="package://larcc_cell_description/meshes/minitec_90x90_2200.STL" scale="0.001 0.001 0.001"/>
      </geometry>
      <material name="grey"/>
    </visual>
    <collision>
      <origin xyz="0.045 0.045 1.1" rpy="0.0 0.0 0.0"/>
      <geometry>
        <box size="0.09 0.09 2.2"/>
      </geometry>
    </collision>
  </link>
  <gazebo reference="leg2_gantry">
    <material>Gazebo/Grey</material>
    <mu1>1000.0</mu1>
    <mu2>1000.0</mu2>
    <kp>10000000.0</kp>
    <kd>1.0</kd>
    <selfCollide>true</selfCollide>
  </gazebo>
  <joint name="gantry_to_leg2" type="fixed">
    <origin xyz="2.0 1.39875 0.065" rpy="0.0 0.0 0.0"/>
    <parent link="gantry"/>
    <child link="leg2_gantry"/>
  </joint>
  <link name="leg3_gantry">
    <inertial>
      <origin xyz="0.0 0.0 1.1440000000000001" rpy="0.0 0.0 0.0"/>
      <mass value="1.0"/>
      <inertia ixx="0.1" ixy="0.0" ixz="0.0" iyy="0.1" iyz="0.0" izz="0.01"/>
    </inertial>
    <visual>
      <origin xyz="0.0 0.0 0.0" rpy="0.0 0.0 0.0"/>
      <geometry>
        <mesh filename="package://larcc_cell_description/meshes/minitec_90x90_2200.STL" scale="0.001 0.001 0.001"/>
      </geometry>
      <material name="grey"/>
    </visual>
    <collision>
      <origin xyz="0.045 0.045 1.1" rpy="0.0 0.0 0.0"/>
      <geometry>
        <box size="0.09 0.09 2.2"/>
      </geometry>
    </collision>
  </link>
  <gazebo reference="leg3_gantry">
    <material>Gazebo/Grey</material>
    <mu1>1000.0</mu1>
    <mu2>1000.0</mu2>
    <kp>10000000.0</kp>
    <kd>1.0</kd>
    <selfCollide>true</selfCollide>
  </gazebo>
  <joint name="gantry_to_leg3" type="fixed">
    <origin xyz="2.0 -1.48875 0.065" rpy="0.0 0.0 0.0"/>
    <parent link="gantry"/>
    <child link="leg3_gantry"/>
  </joint>
  <link name="leg4_gantry">
    <inertial>
      <origin xyz="0.0 0.0 1.1440000000000001" rpy="0.0 0.0 0.0"/>
      <mass value="1.0"/>
      <inertia ixx="0.1" ixy="0.0" ixz="0.0" iyy="0.1" iyz="0.0" izz="0.01"/>
    </inertial>
    <visual>
      <origin xyz="0.0 0.0 0.0" rpy="0.0 0.0 0.0"/>
      <geometry>
        <mesh filename="package://larcc_cell_description/meshes/minitec_90x90_2200.STL" scale="0.001 0.001 0.001"/>
      </geometry>
      <material name="grey"/>
    </visual>
    <collision>
      <origin xyz="0.045 0.045 1.1" rpy="0.0 0.0 0.0"/>
      <geometry>
        <box size="0.09 0.09 2.2"/>
      </geometry>
    </collision>
  </link>
  <gazebo reference="leg4_gantry">
    <material>Gazebo/Grey</material>
    <mu1>1000.0</mu1>
    <mu2>1000.0</mu2>
    <kp>10000000.0</kp>
    <kd>1.0</kd>
    <selfCollide>true</selfCollide>
  </gazebo>
  <joint name="gantry_to_leg4" type="fixed">
    <origin xyz="-2.09 -1.48875 0.065" rpy="0.0 0.0 0.0"/>
    <parent link="gantry"/>
    <child link="leg4_gantry"/>
  </joint>
  <link name="bigbeam1_gantry">
    <inertial>
      <origin xyz="0.0 0.0 1.1440000000000001" rpy="0.0 0.0 0.0"/>
      <mass value="1.0"/>
      <inertia ixx="0.1" ixy="0.0" ixz="0.0" iyy="0.1" iyz="0.0" izz="0.01"/>
    </inertial>
    <visual>
      <origin xyz="0.0 0.0 0.0" rpy="0.0 1.5707963267948966 0.0"/>
      <geometry>
        <mesh filename="package://larcc_cell_description/meshes/minitec_90x90_5000.STL" scale="0.001 0.001 0.001"/>
      </geometry>
      <material name="grey"/>
    </visual>
    <collision>
      <origin xyz="2.5 0.045 -0.045" rpy="0.0 1.5707963267948966 0.0"/>
      <geometry>
        <box size="0.09 0.09 5.0"/>
      </geometry>
    </collision>
  </link>
  <gazebo reference="bigbeam1_leg1_gantry">
    <material>Gazebo/Grey</material>
    <mu1>1000.0</mu1>
    <mu2>1000.0</mu2>
    <kp>10000000.0</kp>
    <kd>1.0</kd>
    <selfCollide>true</selfCollide>
  </gazebo>
  <joint name="leg1_gantry_to_bigbeam1" type="fixed">
    <origin xyz="-0.315 0.0 2.29" rpy="0.0 0.0 0.0"/>
    <parent link="leg1_gantry"/>
    <child link="bigbeam1_gantry"/>
  </joint>
  <link name="bigbeam2_gantry">
    <inertial>
      <origin xyz="0.0 0.0 1.1440000000000001" rpy="0.0 0.0 0.0"/>
      <mass value="1.0"/>
      <inertia ixx="0.1" ixy="0.0" ixz="0.0" iyy="0.1" iyz="0.0" izz="0.01"/>
    </inertial>
    <visual>
      <origin xyz="0.0 0.0 0.0" rpy="0.0 1.5707963267948966 0.0"/>
      <geometry>
        <mesh filename="package://larcc_cell_description/meshes/minitec_90x90_5000.STL" scale="0.001 0.001 0.001"/>
      </geometry>
      <material name="grey"/>
    </visual>
    <collision>
      <origin xyz="2.5 0.045 -0.045" rpy="0.0 1.5707963267948966 0.0"/>
      <geometry>
        <box size="0.09 0.09 5.0"/>
      </geometry>
    </collision>
  </link>
  <gazebo reference="bigbeam2_leg4_gantry">
    <material>Gazebo/Grey</material>
    <mu1>1000.0</mu1>
    <mu2>1000.0</mu2>
    <kp>10000000.0</kp>
    <kd>1.0</kd>
    <selfCollide>true</selfCollide>
  </gazebo>
  <joint name="leg4_gantry_to_bigbeam2" type="fixed">
    <origin xyz="-0.315 0.0 2.29" rpy="0.0 0.0 0.0"/>
    <parent link="leg4_gantry"/>
    <child link="bigbeam2_gantry"/>
  </joint>
  <link name="smallbeam1_bigbeam1_gantry">
    <inertial>
      <origin xyz="0.0 0.0 1.1440000000000001" rpy="0.0 0.0 0.0"/>
      <mass value="1.0"/>
      <inertia ixx="0.1" ixy="0.0" ixz="0.0" iyy="0.1" iyz="0.0" izz="0.01"/>
    </inertial>
    <visual>
      <origin xyz="0.0 0.0 0.0" rpy="0.0 1.5707963267948966 1.5707963267948966"/>
      <geometry>
        <mesh filename="package://larcc_cell_description/meshes/minitec_90x90_3800.STL" scale="0.001 0.001 0.001"/>
      </geometry>
      <material name="grey"/>
    </visual>
    <collision>
      <origin xyz="-0.045 1.9 -0.045" rpy="0.0 1.5707963267948966 1.5707963267948966"/>
      <geometry>
        <box size="0.09 0.09 3.8"/>
      </geometry>
    </collision>
  </link>
  <gazebo reference="smallbeam1_bigbeam1_gantry">
    <material>Gazebo/Grey</material>
    <mu1>1000.0</mu1>
    <mu2>1000.0</mu2>
    <kp>10000000.0</kp>
    <kd>1.0</kd>
    <selfCollide>true</selfCollide>
  </gazebo>
  <joint name="bigbeam1_gantry_to_smallbeam1" type="fixed">
    <origin xyz="0.41000000000000003 -3.2575 0.09" rpy="0.0 0.0 0.0"/>
    <parent link="bigbeam1_gantry"/>
    <child link="smallbeam1_bigbeam1_gantry"/>
  </joint>
  <link name="smallbeam2_bigbeam1_gantry">
    <inertial>
      <origin xyz="0.0 0.0 1.1440000000000001" rpy="0.0 0.0 0.0"/>
      <mass value="1.0"/>
      <inertia ixx="0.1" ixy="0.0" ixz="0.0" iyy="0.1" iyz="0.0" izz="0.01"/>
    </inertial>
    <visual>
      <origin xyz="0.0 0.0 0.0" rpy="0.0 1.5707963267948966 1.5707963267948966"/>
      <geometry>
        <mesh filename="package://larcc_cell_description/meshes/minitec_90x90_3800.STL" scale="0.001 0.001 0.001"/>
      </geometry>
      <material name="grey"/>
    </visual>
    <collision>
      <origin xyz="-0.045 1.9 -0.045" rpy="0.0 1.5707963267948966 1.5707963267948966"/>
      <geometry>
        <box size="0.09 0.09 3.8"/>
      </geometry>
    </collision>
  </link>
  <gazebo reference="smallbeam2_bigbeam1_gantry">
    <material>Gazebo/Grey</material>
    <mu1>1000.0</mu1>
    <mu2>1000.0</mu2>
    <kp>10000000.0</kp>
    <kd>1.0</kd>
    <selfCollide>true</selfCollide>
  </gazebo>
  <joint name="bigbeam1_gantry_to_smallbeam2" type="fixed">
    <origin xyz="4.5 -3.2575 0.09" rpy="0.0 0.0 0.0"/>
    <parent link="bigbeam1_gantry"/>
    <child link="smallbeam2_bigbeam1_gantry"/>
  </joint>
  <link name="rectangularbeam1_gantry">
    <inertial>
      <origin xyz="0.0 0.0 1.1440000000000001" rpy="0.0 0.0 0.0"/>
      <mass value="1.0"/>
      <inertia ixx="0.1" ixy="0.0" ixz="0.0" iyy="0.1" iyz="0.0" izz="0.01"/>
    </inertial>
    <visual>
      <origin xyz="0.0 0.0 0.0" rpy="0.0 1.5707963267948966 1.5707963267948966"/>
      <geometry>
        <mesh filename="package://larcc_cell_description/meshes/minitec_45x90_3000.STL" scale="0.001 0.001 0.001"/>
      </geometry>
      <material name="grey"/>
    </visual>
    <collision>
      <origin xyz="-0.045 1.5 -0.0225" rpy="0.0 1.5707963267948966 1.5707963267948966"/>
      <geometry>
        <box size="0.045 0.09 3.0"/>
      </geometry>
    </collision>
  </link>
  <gazebo reference="rectangularbeam1_bigbeam1_gantry">
    <material>Gazebo/Grey</material>
    <mu1>1000.0</mu1>
    <mu2>1000.0</mu2>
    <kp>10000000.0</kp>
    <kd>1.0</kd>
    <selfCollide>true</selfCollide>
  </gazebo>
  <joint name="bigbeam1_gantry_to_rectangularbeam1" type="fixed">
    <origin xyz="1.435 -3.0075 0.0" rpy="0.0 1.5707963267948966 0.0"/>
    <parent link="bigbeam1_gantry"/>
    <child link="rectangularbeam1_gantry"/>
  </joint>
  <link name="rectangularbeam2_gantry">
    <inertial>
      <origin xyz="0.0 0.0 1.1440000000000001" rpy="0.0 0.0 0.0"/>
      <mass value="1.0"/>
      <inertia ixx="0.1" ixy="0.0" ixz="0.0" iyy="0.1" iyz="0.0" izz="0.01"/>
    </inertial>
    <visual>
      <origin xyz="0.0 0.0 0.0" rpy="0.0 1.5707963267948966 1.5707963267948966"/>
      <geometry>
        <mesh filename="package://larcc_cell_description/meshes/minitec_45x90_3000.STL" scale="0.001 0.001 0.001"/>
      </geometry>
      <material name="grey"/>
    </visual>
    <collision>
      <origin xyz="-0.045 1.5 -0.0225" rpy="0.0 1.5707963267948966 1.5707963267948966"/>
      <geometry>
        <box size="0.045 0.09 3.0"/>
      </geometry>
    </collision>
  </link>
  <gazebo reference="rectangularbeam2_bigbeam1_gantry">
    <material>Gazebo/Grey</material>
    <mu1>1000.0</mu1>
    <mu2>1000.0</mu2>
    <kp>10000000.0</kp>
    <kd>1.0</kd>
    <selfCollide>true</selfCollide>
  </gazebo>
  <joint name="bigbeam1_gantry_to_rectangularbeam2" type="fixed">
    <origin xyz="2.425 -3.0075 0.0" rpy="0.0 1.5707963267948966 0.0"/>
    <parent link="bigbeam1_gantry"/>
    <child link="rectangularbeam2_gantry"/>
  </joint>
  <link name="rectangularbeam3_gantry">
    <inertial>
      <origin xyz="0.0 0.0 1.1440000000000001" rpy="0.0 0.0 0.0"/>
      <mass value="1.0"/>
      <inertia ixx="0.1" ixy="0.0" ixz="0.0" iyy="0.1" iyz="0.0" izz="0.01"/>
    </inertial>
    <visual>
      <origin xyz="0.0 0.0 0.0" rpy="0.0 1.5707963267948966 1.5707963267948966"/>
      <geometry>
        <mesh filename="package://larcc_cell_description/meshes/minitec_45x90_3000.STL" scale="0.001 0.001 0.001"/>
      </geometry>
      <material name="grey"/>
    </visual>
    <collision>
      <origin xyz="-0.045 1.5 -0.0225" rpy="0.0 1.5707963267948966 1.5707963267948966"/>
      <geometry>
        <box size="0.045 0.09 3.0"/>
      </geometry>
    </collision>
  </link>
  <gazebo reference="rectangularbeam3_bigbeam1_gantry">
    <material>Gazebo/Grey</material>
    <mu1>1000.0</mu1>
    <mu2>1000.0</mu2>
    <kp>10000000.0</kp>
    <kd>1.0</kd>
    <selfCollide>true</selfCollide>
  </gazebo>
  <joint name="bigbeam1_gantry_to_rectangularbeam3" type="fixed">
    <origin xyz="3.425 -3.0075 0.0" rpy="0.0 1.5707963267948966 0.0"/>
    <parent link="bigbeam1_gantry"/>
    <child link="rectangularbeam3_gantry"/>
  </joint>
  <transmission name="shoulder_pan_trans">
    <type>transmission_interface/SimpleTransmission</type>
    <joint name="shoulder_pan_joint">
      <hardwareInterface>hardware_interface/PositionJointInterface</hardwareInterface>
    </joint>
    <actuator name="shoulder_pan_motor">
      <mechanicalReduction>1.0</mechanicalReduction>
    </actuator>
  </transmission>
  <transmission name="shoulder_lift_trans">
    <type>transmission_interface/SimpleTransmission</type>
    <joint name="shoulder_lift_joint">
      <hardwareInterface>hardware_interface/PositionJointInterface</hardwareInterface>
    </joint>
    <actuator name="shoulder_lift_motor">
      <mechanicalReduction>1.0</mechanicalReduction>
    </actuator>
  </transmission>
  <transmission name="elbow_trans">
    <type>transmission_interface/SimpleTransmission</type>
    <joint name="elbow_joint">
      <hardwareInterface>hardware_interface/PositionJointInterface</hardwareInterface>
    </joint>
    <actuator name="elbow_motor">
      <mechanicalReduction>1.0</mechanicalReduction>
    </actuator>
  </transmission>
  <transmission name="wrist_1_trans">
    <type>transmission_interface/SimpleTransmission</type>
    <joint name="wrist_1_joint">
      <hardwareInterface>hardware_interface/PositionJointInterface</hardwareInterface>
    </joint>
    <actuator name="wrist_1_motor">
      <mechanicalReduction>1.0</mechanicalReduction>
    </actuator>
  </transmission>
  <transmission name="wrist_2_trans">
    <type>transmission_interface/SimpleTransmission</type>
    <joint name="wrist_2_joint">
      <hardwareInterface>hardware_interface/PositionJointInterface</hardwareInterface>
    </joint>
    <actuator name="wrist_2_motor">
      <mechanicalReduction>1.0</mechanicalReduction>
    </actuator>
  </transmission>
  <transmission name="wrist_3_trans">
    <type>transmission_interface/SimpleTransmission</type>
    <joint name="wrist_3_joint">
      <hardwareInterface>hardware_interface/PositionJointInterface</hardwareInterface>
    </joint>
    <actuator name="wrist_3_motor">
      <mechanicalReduction>1.0</mechanicalReduction>
    </actuator>
  </transmission>
  <link name="base_link"/>
  <link name="base_link_inertia">
    <inertial>
      <origin xyz="0.0 0.0 0.0" rpy="0.0 0.0 0.0"/>
      <mass value="4.0"/>
      <inertia ixx="0.0061063308908" ixy="0.0" ixz="0.0" iyy="0.0061063308908" iyz="0.0" izz="0.01125"/>
    </inertial>
    <visual>
      <origin xyz="0.0 0.0 0.0" rpy="0.0 0.0 3.141592653589793"/>
      <geometry>
        <mesh filename="package://ur_description/meshes/ur10e/visual/base.dae"/>
      </geometry>
      <material name="LightGrey">
        <color rgba="0.7 0.7 0.7 1.0"/>
      </material>
    </visual>
    <collision>
      <origin xyz="0.0 0.0 0.0" rpy="0.0 0.0 3.141592653589793"/>
      <geometry>
        <mesh filename="package://ur_description/meshes/ur10e/collision/base.stl"/>
      </geometry>
    </collision>
  </link>
  <link name="shoulder_link">
    <inertial>
      <origin xyz="0.0 0.0 0.0" rpy="0.0 0.0 0.0"/>
      <mass value="7.778"/>
      <inertia ixx="0.03147431257693659" ixy="0.0" ixz="0.0" iyy="0.03147431257693659" iyz="0.0" izz="0.021875624999999996"/>
    </inertial>
    <visual>
      <origin xyz="0.0 0.0 0.0" rpy="0.0 0.0 3.141592653589793"/>
      <geometry>
        <mesh filename="package://ur_description/meshes/ur10e/visual/shoulder.dae"/>
      </geometry>
      <material name="LightGrey">
        <color rgba="0.7 0.7 0.7 1.0"/>
      </material>
    </visual>
    <collision>
      <origin xyz="0.0 0.0 0.0" rpy="0.0 0.0 3.141592653589793"/>
      <geometry>
        <mesh filename="package://ur_description/meshes/ur10e/collision/shoulder.stl"/>
      </geometry>
    </collision>
  </link>
  <link name="upper_arm_link">
    <inertial>
      <origin xyz="-0.306 0.0 0.175" rpy="0.0 1.5707963267948966 0.0"/>
      <mass value="12.93"/>
      <inertia ixx="0.42175380379841093" ixy="0.0" ixz="0.0" iyy="0.42175380379841093" iyz="0.0" izz="0.03636562499999999"/>
    </inertial>
    <visual>
      <origin xyz="0.0 0.0 0.1762" rpy="1.5707963267948966 0.0 -1.5707963267948966"/>
      <geometry>
        <mesh filename="package://ur_description/meshes/ur10e/visual/upperarm.dae"/>
      </geometry>
      <material name="LightGrey">
        <color rgba="0.7 0.7 0.7 1.0"/>
      </material>
    </visual>
    <collision>
      <origin xyz="0.0 0.0 0.1762" rpy="1.5707963267948966 0.0 -1.5707963267948966"/>
      <geometry>
        <mesh filename="package://ur_description/meshes/ur10e/collision/upperarm.stl"/>
      </geometry>
    </collision>
  </link>
  <link name="forearm_link">
    <inertial>
      <origin xyz="-0.285775 0.0 0.0393" rpy="0.0 1.5707963267948966 0.0"/>
      <mass value="3.87"/>
      <inertia ixx="0.11079302548902206" ixy="0.0" ixz="0.0" iyy="0.11079302548902206" iyz="0.0" izz="0.010884375"/>
    </inertial>
    <visual>
      <origin xyz="0.0 0.0 0.0393" rpy="1.5707963267948966 0.0 -1.5707963267948966"/>
      <geometry>
        <mesh filename="package://ur_description/meshes/ur10e/visual/forearm.dae"/>
      </geometry>
      <material name="LightGrey">
        <color rgba="0.7 0.7 0.7 1.0"/>
      </material>
    </visual>
    <collision>
      <origin xyz="0.0 0.0 0.0393" rpy="1.5707963267948966 0.0 -1.5707963267948966"/>
      <geometry>
        <mesh filename="package://ur_description/meshes/ur10e/collision/forearm.stl"/>
      </geometry>
    </collision>
  </link>
  <link name="wrist_1_link">
    <inertial>
      <origin xyz="0.0 0.0 0.0" rpy="0.0 0.0 0.0"/>
      <mass value="1.96"/>
      <inertia ixx="0.005108247956699999" ixy="0.0" ixz="0.0" iyy="0.005108247956699999" iyz="0.0" izz="0.005512499999999999"/>
    </inertial>
    <visual>
      <origin xyz="0.0 0.0 -0.135" rpy="1.5707963267948966 0.0 0.0"/>
      <geometry>
        <mesh filename="package://ur_description/meshes/ur10e/visual/wrist1.dae"/>
      </geometry>
      <material name="LightGrey">
        <color rgba="0.7 0.7 0.7 1.0"/>
      </material>
    </visual>
    <collision>
      <origin xyz="0.0 0.0 -0.135" rpy="1.5707963267948966 0.0 0.0"/>
      <geometry>
        <mesh filename="package://ur_description/meshes/ur10e/collision/wrist1.stl"/>
      </geometry>
    </collision>
  </link>
  <link name="wrist_2_link">
    <inertial>
      <origin xyz="0.0 0.0 0.0" rpy="0.0 0.0 0.0"/>
      <mass value="1.96"/>
      <inertia ixx="0.005108247956699999" ixy="0.0" ixz="0.0" iyy="0.005108247956699999" iyz="0.0" izz="0.005512499999999999"/>
    </inertial>
    <visual>
      <origin xyz="0.0 0.0 -0.12" rpy="0.0 0.0 0.0"/>
      <geometry>
        <mesh filename="package://ur_description/meshes/ur10e/visual/wrist2.dae"/>
      </geometry>
      <material name="LightGrey">
        <color rgba="0.7 0.7 0.7 1.0"/>
      </material>
    </visual>
    <collision>
      <origin xyz="0.0 0.0 -0.12" rpy="0.0 0.0 0.0"/>
      <geometry>
        <mesh filename="package://ur_description/meshes/ur10e/collision/wrist2.stl"/>
      </geometry>
    </collision>
  </link>
  <link name="wrist_3_link">
    <inertial>
      <origin xyz="0.0 0.0 -0.025" rpy="0.0 0.0 0.0"/>
      <mass value="0.202"/>
      <inertia ixx="0.00014434577559500002" ixy="0.0" ixz="0.0" iyy="0.00014434577559500002" iyz="0.0" izz="0.00020452500000000002"/>
    </inertial>
    <visual>
      <origin xyz="0.0 0.0 -0.1168" rpy="1.5707963267948966 0.0 0.0"/>
      <geometry>
        <mesh filename="package://ur_description/meshes/ur10e/visual/wrist3.dae"/>
      </geometry>
      <material name="LightGrey">
        <color rgba="0.7 0.7 0.7 1.0"/>
      </material>
    </visual>
    <collision>
      <origin xyz="0.0 0.0 -0.1168" rpy="1.5707963267948966 0.0 0.0"/>
      <geometry>
        <mesh filename="package://ur_description/meshes/ur10e/collision/wrist3.stl"/>
      </geometry>
    </collision>
  </link>
  <joint name="base_link-base_link_inertia" type="fixed">
    <origin xyz="0.0 0.0 0.0" rpy="0.0 0.0 3.141592653589793"/>
    <parent link="base_link"/>
    <child link="base_link_inertia"/>
  </joint>
  <joint name="shoulder_pan_joint" type="revolute">
    <origin xyz="0.0 0.0 0.1807" rpy="0.0 0.0 0.0"/>
    <axis xyz="0.0 0.0 1.0"/>
    <parent link="base_link_inertia"/>
    <child link="shoulder_link"/>
    <limit effort="330.0" lower="-2.6179938779914944" upper="2.6179938779914944" velocity="2.0943951023931953"/>
    <dynamics damping="0.0" friction="0.0"/>
  </joint>
  <joint name="shoulder_lift_joint" type="revolute">
    <origin xyz="0.0 0.0 0.0" rpy="1.570796327 0.0 0.0"/>
    <axis xyz="0.0 0.0 1.0"/>
    <parent link="shoulder_link"/>
    <child link="upper_arm_link"/>
    <limit effort="330.0" lower="-2.6179938779914944" upper="-0.5235987755982988" velocity="3.141592653589793"/>
    <dynamics damping="0.0" friction="0.0"/>
  </joint>
  <joint name="elbow_joint" type="revolute">
    <origin xyz="-0.6127 0.0 0.0" rpy="0.0 0.0 0.0"/>
    <axis xyz="0.0 0.0 1.0"/>
    <parent link="upper_arm_link"/>
    <child link="forearm_link"/>
    <limit effort="150.0" lower="0.0" upper="2.9670597283903604" velocity="3.141592653589793"/>
    <dynamics damping="0.0" friction="0.0"/>
  </joint>
  <joint name="wrist_1_joint" type="revolute">
    <origin xyz="-0.57155 0.0 0.17415" rpy="0.0 0.0 0.0"/>
    <axis xyz="0.0 0.0 1.0"/>
    <parent link="forearm_link"/>
    <child link="wrist_1_link"/>
    <limit effort="56.0" lower="-4.71238898038469" upper="0.0" velocity="3.141592653589793"/>
    <dynamics damping="0.0" friction="0.0"/>
  </joint>
  <joint name="wrist_2_joint" type="revolute">
    <origin xyz="0.0 -0.11985 -2.458164590756244e-11" rpy="1.570796327 0.0 0.0"/>
    <axis xyz="0.0 0.0 1.0"/>
    <parent link="wrist_1_link"/>
    <child link="wrist_2_link"/>
    <limit effort="56.0" lower="-3.141592653589793" upper="0.0" velocity="3.141592653589793"/>
    <dynamics damping="0.0" friction="0.0"/>
  </joint>
  <joint name="wrist_3_joint" type="revolute">
    <origin xyz="0.0 0.11655 -2.390480459346185e-11" rpy="1.570796326589793 3.141592653589793 3.141592653589793"/>
    <axis xyz="0.0 0.0 1.0"/>
    <parent link="wrist_2_link"/>
    <child link="wrist_3_link"/>
    <limit effort="56.0" lower="-3.141592653589793" upper="3.141592653589793" velocity="3.141592653589793"/>
    <dynamics damping="0.0" friction="0.0"/>
  </joint>
  <link name="base"/>
  <joint name="base_link-base_fixed_joint" type="fixed">
    <origin xyz="0.0 0.0 0.0" rpy="0.0 0.0 3.141592653589793"/>
    <parent link="base_link"/>
    <child link="base"/>
  </joint>
  <link name="flange"/>
  <joint name="wrist_3-flange" type="fixed">
    <origin xyz="0.0 0.0 0.0" rpy="0.0 -1.5707963267948966 -1.5707963267948966"/>
    <parent link="wrist_3_link"/>
    <child link="flange"/>
  </joint>
  <link name="tool0"/>
  <joint name="flange-tool0" type="fixed">
    <origin xyz="0.0 0.0 0.0" rpy="1.5707963267948966 0.0 1.5707963267948966"/>
    <parent link="flange"/>
    <child link="tool0"/>
  </joint>
  <joint name="world_to_robot_joint" type="fixed">
    <origin xyz="0.0 0.0 -0.015" rpy="0.0 0.0 0.0"/>
    <parent link="tabletop_table_base"/>
    <child link="base_link"/>
  </joint>
  <joint name="camera_behind_rgb_joint" type="fixed">
    <origin xyz="0.8657309349506475 1.1745325907498732 2.358947641663387" rpy="-0.3369602512178866 0.551670213972371 -1.9437147020481422"/>
    <parent link="world"/>
    <child link="camera_behind_link"/>
  </joint>
  <link name="camera_behind_link">
    <inertial>
      <origin xyz="0.0 0.0 0.0" rpy="0 0 0"/>
      <mass value="0.564"/>
      <inertia ixx="0.003881243" ixy="0.0" ixz="0.0" iyy="0.00049894" iyz="0.0" izz="0.003879257"/>
    </inertial>
    <visual>
      <origin xyz="0.0 0.0 0.0" rpy="0.0 3.141592653589793 -1.5707963267948966"/>
      <geometry>
        <mesh filename="package://larcc_cell_description/meshes/sensors/astra2.dae" scale="1.0 1.0 1.0"/>
      </geometry>
    </visual>
    <collision>
      <origin xyz="0.0 0.0 0.0" rpy="0.0 0.0 0.0"/>
      <geometry>
        <box size="0.04 0.165 0.03"/>
      </geometry>
    </collision>
  </link>
  <joint name="camera_behind_joint" type="fixed">
    <origin xyz="0.0 0.01 0.0" rpy="1.5707963267948966 3.141592653589793 1.5707963267948966"/>
    <parent link="camera_behind_link"/>
    <child link="camera_behind_rgb_optical_frame"/>
  </joint>
  <link name="camera_behind_rgb_optical_frame"/>
  <joint name="camera_behind_depth_joint" type="fixed">
    <origin xyz="0.0 0.037 0.0" rpy="1.5707963267948966 3.141592653589793 1.5707963267948966"/>
    <parent link="camera_behind_link"/>
    <child link="camera_behind_depth_optical_frame"/>
  </joint>
  <link name="camera_behind_depth_optical_frame"/>
  <gazebo reference="camera_behind_depth_frame">
    <sensor name="camera" type="depth">
      <always_on>true</always_on>
      <update_rate>8.0</update_rate>
      <camera>
        <horizontal_fov>1.0471975511965976</horizontal_fov>
        <image>
          <format>B8G8R8</format>
          <width>640</width>
          <height>480</height>
        </image>
        <clip>
          <near>0.10</near>
          <far>8.0</far>
        </clip>
      </camera>
      <plugin filename="libgazebo_ros_openni_kinect.so" name="camera_behind_camera_controller">
        <cameraName>camera_behind</cameraName>
        <alwaysOn>true</alwaysOn>
        <updateRate>0</updateRate>
        <imageTopicName>color/image_raw</imageTopicName>
        <depthImageTopicName>depth/image_raw</depthImageTopicName>
        <pointCloudTopicName>depth/points</pointCloudTopicName>
        <cameraInfoTopicName>color/camera_info</cameraInfoTopicName>
        <depthImageCameraInfoTopicName>depth/camera_info</depthImageCameraInfoTopicName>
        <frameName>camera_behind_color_optical_frame</frameName>
        <baseline>0.1</baseline>
        <distortion_k1>0.0</distortion_k1>
        <distortion_k2>0.0</distortion_k2>
        <distortion_k3>0.0</distortion_k3>
        <distortion_t1>0.0</distortion_t1>
        <distortion_t2>0.0</distortion_t2>
        <pointCloudCutoff>0.4</pointCloudCutoff>
      </plugin>
    </sensor>
  </gazebo>
  <joint name="camera_top_rgb_joint" type="fixed">
    <origin xyz="0.05343866423636168 0.14922067354984486 2.4506180537580113" rpy="-1.9217149884618365 1.481938650857729 -2.0217732500248773"/>
    <parent link="world"/>
    <child link="camera_top_link"/>
  </joint>
  <link name="camera_top_link">
    <inertial>
      <origin xyz="0.0 0.0 0.0" rpy="0 0 0"/>
      <mass value="0.564"/>
      <inertia ixx="0.003881243" ixy="0.0" ixz="0.0" iyy="0.00049894" iyz="0.0" izz="0.003879257"/>
    </inertial>
    <visual>
      <origin xyz="0.0 0.0 0.0" rpy="0.0 3.141592653589793 -1.5707963267948966"/>
      <geometry>
        <mesh filename="package://larcc_cell_description/meshes/sensors/astra2.dae" scale="1.0 1.0 1.0"/>
      </geometry>
    </visual>
    <collision>
      <origin xyz="0.0 0.0 0.0" rpy="0.0 0.0 0.0"/>
      <geometry>
        <box size="0.04 0.165 0.03"/>
      </geometry>
    </collision>
  </link>
  <joint name="camera_top_joint" type="fixed">
    <origin xyz="0.0 0.01 0.0" rpy="1.5707963267948966 3.141592653589793 1.5707963267948966"/>
    <parent link="camera_top_link"/>
    <child link="camera_top_rgb_optical_frame"/>
  </joint>
  <link name="camera_top_rgb_optical_frame"/>
  <joint name="camera_top_depth_joint" type="fixed">
    <origin xyz="0.0 0.037 0.0" rpy="1.5707963267948966 3.141592653589793 1.5707963267948966"/>
    <parent link="camera_top_link"/>
    <child link="camera_top_depth_optical_frame"/>
  </joint>
  <link name="camera_top_depth_optical_frame"/>
  <gazebo reference="camera_top_depth_frame">
    <sensor name="camera" type="depth">
      <always_on>true</always_on>
      <update_rate>8.0</update_rate>
      <camera>
        <horizontal_fov>1.0471975511965976</horizontal_fov>
        <image>
          <format>B8G8R8</format>
          <width>640</width>
          <height>480</height>
        </image>
        <clip>
          <near>0.10</near>
          <far>8.0</far>
        </clip>
      </camera>
      <plugin filename="libgazebo_ros_openni_kinect.so" name="camera_top_camera_controller">
        <cameraName>camera_top</cameraName>
        <alwaysOn>true</alwaysOn>
        <updateRate>0</updateRate>
        <imageTopicName>color/image_raw</imageTopicName>
        <depthImageTopicName>depth/image_raw</depthImageTopicName>
        <pointCloudTopicName>depth/points</pointCloudTopicName>
        <cameraInfoTopicName>color/camera_info</cameraInfoTopicName>
        <depthImageCameraInfoTopicName>depth/camera_info</depthImageCameraInfoTopicName>
        <frameName>camera_top_color_optical_frame</frameName>
        <baseline>0.1</baseline>
        <distortion_k1>0.0</distortion_k1>
        <distortion_k2>0.0</distortion_k2>
        <distortion_k3>0.0</distortion_k3>
        <distortion_t1>0.0</distortion_t1>
        <distortion_t2>0.0</distortion_t2>
        <pointCloudCutoff>0.4</pointCloudCutoff>
      </plugin>
    </sensor>
  </gazebo>
  <joint name="camera_right_rgb_joint" type="fixed">
    <origin xyz="-0.48769570892652475 0.6173557198083176 1.2749729084453454" rpy="-0.01007081150556496 0.3626305139780482 -0.7073242087231996"/>
    <parent link="world"/>
    <child link="camera_right_link"/>
  </joint>
  <link name="camera_right_link">
    <inertial>
      <origin xyz="0.0 0.0 0.0" rpy="0 0 0"/>
      <mass value="0.564"/>
      <inertia ixx="0.003881243" ixy="0.0" ixz="0.0" iyy="0.00049894" iyz="0.0" izz="0.003879257"/>
    </inertial>
    <visual>
      <origin xyz="0.0 0.0 0.0" rpy="0.0 3.141592653589793 -1.5707963267948966"/>
      <geometry>
        <mesh filename="package://larcc_cell_description/meshes/sensors/astra2.dae" scale="1.0 1.0 1.0"/>
      </geometry>
    </visual>
    <collision>
      <origin xyz="0.0 0.0 0.0" rpy="0.0 0.0 0.0"/>
      <geometry>
        <box size="0.04 0.165 0.03"/>
      </geometry>
    </collision>
  </link>
  <joint name="camera_right_joint" type="fixed">
    <origin xyz="0.0 0.01 0.0" rpy="1.5707963267948966 3.141592653589793 1.5707963267948966"/>
    <parent link="camera_right_link"/>
    <child link="camera_right_rgb_optical_frame"/>
  </joint>
  <link name="camera_right_rgb_optical_frame"/>
  <joint name="camera_right_depth_joint" type="fixed">
    <origin xyz="0.0 0.037 0.0" rpy="1.5707963267948966 3.141592653589793 1.5707963267948966"/>
    <parent link="camera_right_link"/>
    <child link="camera_right_depth_optical_frame"/>
  </joint>
  <link name="camera_right_depth_optical_frame"/>
  <gazebo reference="camera_right_depth_frame">
    <sensor name="camera" type="depth">
      <always_on>true</always_on>
      <update_rate>8.0</update_rate>
      <camera>
        <horizontal_fov>1.0471975511965976</horizontal_fov>
        <image>
          <format>B8G8R8</format>
          <width>640</width>
          <height>480</height>
        </image>
        <clip>
          <near>0.10</near>
          <far>8.0</far>
        </clip>
      </camera>
      <plugin filename="libgazebo_ros_openni_kinect.so" name="camera_right_camera_controller">
        <cameraName>camera_right</cameraName>
        <alwaysOn>true</alwaysOn>
        <updateRate>0</updateRate>
        <imageTopicName>color/image_raw</imageTopicName>
        <depthImageTopicName>depth/image_raw</depthImageTopicName>
        <pointCloudTopicName>depth/points</pointCloudTopicName>
        <cameraInfoTopicName>color/camera_info</cameraInfoTopicName>
        <depthImageCameraInfoTopicName>depth/camera_info</depthImageCameraInfoTopicName>
        <frameName>camera_right_color_optical_frame</frameName>
        <baseline>0.1</baseline>
        <distortion_k1>0.0</distortion_k1>
        <distortion_k2>0.0</distortion_k2>
        <distortion_k3>0.0</distortion_k3>
        <distortion_t1>0.0</distortion_t1>
        <distortion_t2>0.0</distortion_t2>
        <pointCloudCutoff>0.4</pointCloudCutoff>
      </plugin>
    </sensor>
  </gazebo>
  <joint name="tool0-FT_sensor_base" type="fixed">
    <origin xyz="0.0 0.0 0.007" rpy="0.0 0.0 1.5707963267948966"/>
    <parent link="tool0"/>
    <child link="FT_sensor_base"/>
  </joint>
  <link name="FT_sensor_base">
    <visual>
      <geometry>
        <cylinder radius="0.05" length="0.014"/>
      </geometry>
      <material name="metalic_blue">
        <color rgba="0.0118 0.5176 0.6706 1.0"/>
      </material>
    </visual>
    <collision>
      <geometry>
        <cylinder radius="0.05" length="0.014"/>
      </geometry>
    </collision>
  </link>
  <joint name="FT_sensor_base-FT_sensor" type="fixed">
    <origin xyz="0.0 0.0 0.0215" rpy="0.0 0.0 0.0"/>
    <parent link="FT_sensor_base"/>
    <child link="FT_sensor"/>
  </joint>
  <link name="FT_sensor">
    <visual>
      <geometry>
        <cylinder radius="0.04" length="0.029"/>
      </geometry>
      <material name="metalic_blue">
        <color rgba="0.0118 0.5176 0.6706 1.0"/>
      </material>
    </visual>
    <collision>
      <geometry>
        <cylinder radius="0.04" length="0.029"/>
      </geometry>
    </collision>
  </link>
  <link name="robotiq_arg2f_base_link">
    <inertial>
      <origin xyz="8.625e-08 -4.6583e-06 0.03145" rpy="0.0 0.0 0.0"/>
      <mass value="0.22652"/>
      <inertia ixx="0.00020005" ixy="-4.2442e-10" ixz="-2.9069e-10" iyy="0.00017832" iyz="-3.4402e-08" izz="0.00013478"/>
    </inertial>
    <visual>
      <origin xyz="0.0 0.0 0.0" rpy="0.0 0.0 0.0"/>
      <geometry>
        <mesh filename="package://gripper/meshes/visual/robotiq_arg2f_base_link.stl"/>
      </geometry>
      <material name="">
        <color rgba="0.1 0.1 0.1 1.0"/>
      </material>
    </visual>
    <collision>
      <origin xyz="0.0 0.0 0.0" rpy="0.0 0.0 0.0"/>
      <geometry>
        <mesh filename="package://gripper/meshes/collision/robotiq_arg2f_base_link.stl"/>
      </geometry>
    </collision>
  </link>
  <link name="left_outer_knuckle">
    <inertial>
      <origin xyz="-0.000200000000003065 0.0199435877845359 0.0292245259211331" rpy="0.0 0.0 0.0"/>
      <mass value="0.00853198276973456"/>
      <inertia ixx="2.89328108496468e-06" ixy="-1.57935047237397e-19" ixz="-1.93980378593255e-19" iyy="1.86719750325683e-06" iyz="-1.21858577871576e-06" izz="1.21905238907251e-06"/>
    </inertial>
    <visual>
      <origin xyz="0.0 0.0 0.0" rpy="0.0 0.0 0.0"/>
      <geometry>
        <mesh filename="package://gripper/meshes/visual/robotiq_arg2f_140_outer_knuckle.stl"/>
      </geometry>
      <material name="">
        <color rgba="0.792156862745098 0.819607843137255 0.933333333333333 1.0"/>
      </material>
    </visual>
    <collision>
      <origin xyz="0.0 0.0 0.0" rpy="0.0 0.0 0.0"/>
      <geometry>
        <mesh filename="package://gripper/meshes/collision/robotiq_arg2f_140_outer_knuckle.stl"/>
      </geometry>
    </collision>
  </link>
  <link name="left_outer_finger">
    <inertial>
      <origin xyz="0.00030115855001899 0.0373907951953854 -0.0208027427000385" rpy="0.0 0.0 0.0"/>
      <mass value="0.022614240507152"/>
      <inertia ixx="1.52518312458174e-05" ixy="9.76583423954399e-10" ixz="-5.43838577022588e-10" iyy="6.17694243867776e-06" iyz="6.78636130740228e-06" izz="1.16494917907219e-05"/>
    </inertial>
    <visual>
      <origin xyz="0.0 0.0 0.0" rpy="0.0 0.0 0.0"/>
      <geometry>
        <mesh filename="package://gripper/meshes/visual/robotiq_arg2f_140_outer_finger.stl"/>
      </geometry>
      <material name="">
        <color rgba="0.1 0.1 0.1 1.0"/>
      </material>
    </visual>
    <collision>
      <origin xyz="0.0 0.0 0.0" rpy="0.0 0.0 0.0"/>
      <geometry>
        <mesh filename="package://gripper/meshes/collision/robotiq_arg2f_140_outer_finger.stl"/>
      </geometry>
    </collision>
  </link>
  <link name="left_inner_finger">
    <inertial>
      <origin xyz="0.000299999999999317 0.0160078233491243 -0.0136945669206257" rpy="0.0 0.0 0.0"/>
      <mass value="0.0104003125914103"/>
      <inertia ixx="2.71909453810972e-06" ixy="1.35402465472579e-21" ixz="-7.1817349065269e-22" iyy="7.69100314106116e-07" iyz="6.74715432769696e-07" izz="2.30315190420171e-06"/>
    </inertial>
    <visual>
      <origin xyz="0.0 0.0 0.0" rpy="0.0 0.0 0.0"/>
      <geometry>
        <mesh filename="package://gripper/meshes/visual/robotiq_arg2f_140_inner_finger.stl"/>
      </geometry>
      <material name="">
        <color rgba="0.1 0.1 0.1 1.0"/>
      </material>
    </visual>
    <collision>
      <origin xyz="0.0 0.0 0.0" rpy="0.0 0.0 0.0"/>
      <geometry>
        <mesh filename="package://gripper/meshes/collision/robotiq_arg2f_140_inner_finger.stl"/>
      </geometry>
    </collision>
  </link>
  <link name="left_inner_finger_pad">
    <visual>
      <origin xyz="0.0 0.0 0.0" rpy="0.0 0.0 0.0"/>
      <geometry>
        <box size="0.027 0.065 0.0075"/>
      </geometry>
      <material name="">
        <color rgba="0.9 0.9 0.9 1.0"/>
      </material>
    </visual>
    <collision>
      <origin xyz="0.0 0.0 0.0" rpy="0.0 0.0 0.0"/>
      <geometry>
        <box size="0.03 0.07 0.0075"/>
      </geometry>
    </collision>
  </link>
  <link name="left_inner_knuckle">
    <inertial>
      <origin xyz="0.000123011831763771 0.0507850843201817 0.00103968640075166" rpy="0.0 0.0 0.0"/>
      <mass value="0.0271177346495152"/>
      <inertia ixx="2.61910379223783e-05" ixy="-2.43616858946494e-07" ixz="-6.37789906117123e-09" iyy="2.8270243746167e-06" iyz="-5.37200748039765e-07" izz="2.83695868220296e-05"/>
    </inertial>
    <visual>
      <origin xyz="0.0 0.0 0.0" rpy="0.0 0.0 0.0"/>
      <geometry>
        <mesh filename="package://gripper/meshes/visual/robotiq_arg2f_140_inner_knuckle.stl"/>
      </geometry>
      <material name="">
        <color rgba="0.1 0.1 0.1 1.0"/>
      </material>
    </visual>
    <collision>
      <origin xyz="0.0 0.0 0.0" rpy="0.0 0.0 0.0"/>
      <geometry>
        <mesh filename="package://gripper/meshes/collision/robotiq_arg2f_140_inner_knuckle.stl"/>
      </geometry>
    </collision>
  </link>
  <link name="right_outer_knuckle">
    <inertial>
      <origin xyz="-0.000200000000003065 0.0199435877845359 0.0292245259211331" rpy="0.0 0.0 0.0"/>
      <mass value="0.00853198276973456"/>
      <inertia ixx="2.89328108496468e-06" ixy="-1.57935047237397e-19" ixz="-1.93980378593255e-19" iyy="1.86719750325683e-06" iyz="-1.21858577871576e-06" izz="1.21905238907251e-06"/>
    </inertial>
    <visual>
      <origin xyz="0.0 0.0 0.0" rpy="0.0 0.0 0.0"/>
      <geometry>
        <mesh filename="package://gripper/meshes/visual/robotiq_arg2f_140_outer_knuckle.stl"/>
      </geometry>
      <material name="">
        <color rgba="0.792156862745098 0.819607843137255 0.933333333333333 1.0"/>
      </material>
    </visual>
    <collision>
      <origin xyz="0.0 0.0 0.0" rpy="0.0 0.0 0.0"/>
      <geometry>
        <mesh filename="package://gripper/meshes/collision/robotiq_arg2f_140_outer_knuckle.stl"/>
      </geometry>
    </collision>
  </link>
  <link name="right_outer_finger">
    <inertial>
      <origin xyz="0.00030115855001899 0.0373907951953854 -0.0208027427000385" rpy="0.0 0.0 0.0"/>
      <mass value="0.022614240507152"/>
      <inertia ixx="1.52518312458174e-05" ixy="9.76583423954399e-10" ixz="-5.43838577022588e-10" iyy="6.17694243867776e-06" iyz="6.78636130740228e-06" izz="1.16494917907219e-05"/>
    </inertial>
    <visual>
      <origin xyz="0.0 0.0 0.0" rpy="0.0 0.0 0.0"/>
      <geometry>
        <mesh filename="package://gripper/meshes/visual/robotiq_arg2f_140_outer_finger.stl"/>
      </geometry>
      <material name="">
        <color rgba="0.1 0.1 0.1 1.0"/>
      </material>
    </visual>
    <collision>
      <origin xyz="0.0 0.0 0.0" rpy="0.0 0.0 0.0"/>
      <geometry>
        <mesh filename="package://gripper/meshes/collision/robotiq_arg2f_140_outer_finger.stl"/>
      </geometry>
    </collision>
  </link>
  <link name="right_inner_finger">
    <inertial>
      <origin xyz="0.000299999999999317 0.0160078233491243 -0.0136945669206257" rpy="0.0 0.0 0.0"/>
      <mass value="0.0104003125914103"/>
      <inertia ixx="2.71909453810972e-06" ixy="1.35402465472579e-21" ixz="-7.1817349065269e-22" iyy="7.69100314106116e-07" iyz="6.74715432769696e-07" izz="2.30315190420171e-06"/>
    </inertial>
    <visual>
      <origin xyz="0.0 0.0 0.0" rpy="0.0 0.0 0.0"/>
      <geometry>
        <mesh filename="package://gripper/meshes/visual/robotiq_arg2f_140_inner_finger.stl"/>
      </geometry>
      <material name="">
        <color rgba="0.1 0.1 0.1 1.0"/>
      </material>
    </visual>
    <collision>
      <origin xyz="0.0 0.0 0.0" rpy="0.0 0.0 0.0"/>
      <geometry>
        <mesh filename="package://gripper/meshes/collision/robotiq_arg2f_140_inner_finger.stl"/>
      </geometry>
    </collision>
  </link>
  <link name="right_inner_finger_pad">
    <visual>
      <origin xyz="0.0 0.0 0.0" rpy="0.0 0.0 0.0"/>
      <geometry>
        <box size="0.027 0.065 0.0075"/>
      </geometry>
      <material name="">
        <color rgba="0.9 0.9 0.9 1.0"/>
      </material>
    </visual>
    <collision>
      <origin xyz="0.0 0.0 0.0" rpy="0.0 0.0 0.0"/>
      <geometry>
        <box size="0.03 0.07 0.0075"/>
      </geometry>
    </collision>
  </link>
  <link name="right_inner_knuckle">
    <inertial>
      <origin xyz="0.000123011831763771 0.0507850843201817 0.00103968640075166" rpy="0.0 0.0 0.0"/>
      <mass value="0.0271177346495152"/>
      <inertia ixx="2.61910379223783e-05" ixy="-2.43616858946494e-07" ixz="-6.37789906117123e-09" iyy="2.8270243746167e-06" iyz="-5.37200748039765e-07" izz="2.83695868220296e-05"/>
    </inertial>
    <visual>
      <origin xyz="0.0 0.0 0.0" rpy="0.0 0.0 0.0"/>
      <geometry>
        <mesh filename="package://gripper/meshes/visual/robotiq_arg2f_140_inner_knuckle.stl"/>
      </geometry>
      <material name="">
        <color rgba="0.1 0.1 0.1 1.0"/>
      </material>
    </visual>
    <collision>
      <origin xyz="0.0 0.0 0.0" rpy="0.0 0.0 0.0"/>
      <geometry>
        <mesh filename="package://gripper/meshes/collision/robotiq_arg2f_140_inner_knuckle.stl"/>
      </geometry>
    </collision>
  </link>
  <joint name="finger_joint" type="fixed">
    <origin xyz="0.0 -0.030601 0.054905" rpy="2.2957963267948966 0.0 0.0"/>
    <axis xyz="-1.0 0.0 0.0"/>
    <parent link="robotiq_arg2f_base_link"/>
    <child link="left_outer_knuckle"/>
    <limit effort="1000.0" lower="0.0" upper="0.7" velocity="2.0"/>
  </joint>
  <joint name="left_outer_finger_joint" type="fixed">
    <origin xyz="0.0 0.01821998610742 0.0260018192872234" rpy="0.0 0.0 0.0"/>
    <axis xyz="1.0 0.0 0.0"/>
    <parent link="left_outer_knuckle"/>
    <child link="left_outer_finger"/>
  </joint>
  <joint name="left_inner_knuckle_joint" type="fixed">
    <origin xyz="0.0 -0.0127 0.06142" rpy="2.2957963267948966 0.0 0.0"/>
    <axis xyz="1.0 0.0 0.0"/>
    <parent link="robotiq_arg2f_base_link"/>
    <child link="left_inner_knuckle"/>
    <limit effort="1000.0" lower="-0.8757" upper="0.8757" velocity="2.0"/>
    <mimic joint="finger_joint" multiplier="-1.0" offset="0.0"/>
  </joint>
  <joint name="left_inner_finger_joint" type="fixed">
    <origin xyz="0.0 0.0817554015893473 -0.0282203446692936" rpy="-0.725 0.0 0.0"/>
    <axis xyz="1.0 0.0 0.0"/>
    <parent link="left_outer_finger"/>
    <child link="left_inner_finger"/>
    <limit effort="1000.0" lower="-0.8757" upper="0.8757" velocity="2.0"/>
    <mimic joint="finger_joint" multiplier="1.0" offset="0.0"/>
  </joint>
  <joint name="left_inner_finger_pad_joint" type="fixed">
    <origin xyz="0.0 0.0457554015893473 -0.0272203446692936" rpy="0.0 0.0 0.0"/>
    <axis xyz="0.0 0.0 1.0"/>
    <parent link="left_inner_finger"/>
    <child link="left_inner_finger_pad"/>
  </joint>
  <joint name="right_outer_knuckle_joint" type="fixed">
    <origin xyz="0.0 0.030601 0.054905" rpy="2.2957963267948966 0.0 3.141592653589793"/>
    <axis xyz="1.0 0.0 0.0"/>
    <parent link="robotiq_arg2f_base_link"/>
    <child link="right_outer_knuckle"/>
    <limit effort="1000.0" lower="-0.725" upper="0.725" velocity="2.0"/>
    <mimic joint="finger_joint" multiplier="-1.0" offset="0.0"/>
  </joint>
  <joint name="right_outer_finger_joint" type="fixed">
    <origin xyz="0.0 0.01821998610742 0.0260018192872234" rpy="0.0 0.0 0.0"/>
    <axis xyz="1.0 0.0 0.0"/>
    <parent link="right_outer_knuckle"/>
    <child link="right_outer_finger"/>
  </joint>
  <joint name="right_inner_knuckle_joint" type="fixed">
    <origin xyz="0.0 0.0127 0.06142" rpy="2.2957963267948966 0.0 -3.141592653589793"/>
    <axis xyz="1.0 0.0 0.0"/>
    <parent link="robotiq_arg2f_base_link"/>
    <child link="right_inner_knuckle"/>
    <limit effort="1000.0" lower="-0.8757" upper="0.8757" velocity="2.0"/>
    <mimic joint="finger_joint" multiplier="-1.0" offset="0.0"/>
  </joint>
  <joint name="right_inner_finger_joint" type="fixed">
    <origin xyz="0.0 0.0817554015893473 -0.0282203446692936" rpy="-0.725 0.0 0.0"/>
    <axis xyz="1.0 0.0 0.0"/>
    <parent link="right_outer_finger"/>
    <child link="right_inner_finger"/>
    <limit effort="1000.0" lower="-0.8757" upper="0.8757" velocity="2.0"/>
    <mimic joint="finger_joint" multiplier="1.0" offset="0.0"/>
  </joint>
  <joint name="right_inner_finger_pad_joint" type="fixed">
    <origin xyz="0.0 0.0457554015893473 -0.0272203446692936" rpy="0.0 0.0 0.0"/>
    <axis xyz="0.0 0.0 1.0"/>
    <parent link="right_inner_finger"/>
    <child link="right_inner_finger_pad"/>
  </joint>
  <transmission name="finger_joint_trans">
    <type>transmission_interface/SimpleTransmission</type>
    <joint name="finger_joint">
      <hardwareInterface>PositionJointInterface</hardwareInterface>
    </joint>
    <actuator name="finger_joint_motor">
      <mechanicalReduction>1.0</mechanicalReduction>
    </actuator>
  </transmission>
  <joint name="gripper_joint" type="fixed">
    <origin xyz="0.0 0.0 0.0215" rpy="0.0 0.0 0.0"/>
    <parent link="FT_sensor"/>
    <child link="robotiq_arg2f_base_link"/>
  </joint>
  <link name="end_effector"/>
  <joint name="gripper-end_effector" type="fixed">
    <origin xyz="0.0 0.0 0.21573113136562894" rpy="0.0 0.0 -1.5707963267948966"/>
    <parent link="robotiq_arg2f_base_link"/>
    <child link="end_effector"/>
  </joint>
  <link name="table_base"/>
  <joint name="world_to_table_base" type="fixed">
    <origin xyz="0.1 0.94875 0.0" rpy="0.0 0.0 -1.5707963267948966"/>
    <parent link="world"/>
    <child link="table_base"/>
  </joint>
  <link name="tabletop_table_base">
    <inertial>
      <origin xyz="0.0 0.0 -0.015" rpy="0.0 0.0 0.0"/>
      <mass value="1.0"/>
      <inertia ixx="1.0" ixy="0.0" ixz="0.0" iyy="1.0" iyz="0.0" izz="1.0"/>
    </inertial>
    <visual>
      <origin xyz="0.0 0.0 -0.015" rpy="0.0 0.0 0.0"/>
      <geometry>
        <box size="0.9 1.25 0.015"/>
      </geometry>
      <material name="grey"/>
    </visual>
    <collision name="base_link_collision">
      <origin xyz="0.0 0.0 -0.015" rpy="0.0 0.0 0.0"/>
      <geometry>
        <box size="0.9 1.25 0.015"/>
      </geometry>
    </collision>
  </link>
  <gazebo reference="tabletop_table_base">
    <material>Gazebo/Grey</material>
    <mu1>50.0</mu1>
    <mu2>50.0</mu2>
    <kp>1000000.0</kp>
    <kd>1.0</kd>
    <selfCollide>false</selfCollide>
  </gazebo>
  <joint name="table_base_to_tabletop_table_base" type="fixed">
    <origin xyz="0.0 0.0 0.795" rpy="0.0 0.0 0.0"/>
    <parent link="table_base"/>
    <child link="tabletop_table_base"/>
  </joint>
  <link name="leg1_table_base">
    <inertial>
      <origin xyz="0.0 0.0 0.3815" rpy="0.0 0.0 0.0"/>
      <mass value="1.0"/>
      <inertia ixx="0.1" ixy="0.0" ixz="0.0" iyy="0.1" iyz="0.0" izz="0.01"/>
    </inertial>
    <visual>
      <origin xyz="0.0 0.0 0.3815" rpy="0.0 0.0 0.0"/>
      <geometry>
        <cylinder radius="0.02" length="0.78"/>
      </geometry>
      <material name="grey"/>
    </visual>
    <collision>
      <origin xyz="0.0 0.0 0.3975" rpy="0.0 0.0 0.0"/>
      <geometry>
        <cylinder radius="0.02" length="0.779"/>
      </geometry>
    </collision>
  </link>
  <gazebo reference="leg1_table_base">
    <material>Gazebo/Grey</material>
    <mu1>1000.0</mu1>
    <mu2>1000.0</mu2>
    <kp>10000000.0</kp>
    <kd>1.0</kd>
    <selfCollide>true</selfCollide>
  </gazebo>
  <joint name="table_base_to_leg1" type="fixed">
    <origin xyz="-0.43 0.605 0.0" rpy="0.0 0.0 0.0"/>
    <parent link="table_base"/>
    <child link="leg1_table_base"/>
  </joint>
  <link name="leg2_table_base">
    <inertial>
      <origin xyz="0.0 0.0 0.3815" rpy="0.0 0.0 0.0"/>
      <mass value="1.0"/>
      <inertia ixx="0.1" ixy="0.0" ixz="0.0" iyy="0.1" iyz="0.0" izz="0.01"/>
    </inertial>
    <visual>
      <origin xyz="0.0 0.0 0.3815" rpy="0.0 0.0 0.0"/>
      <geometry>
        <cylinder radius="0.02" length="0.78"/>
      </geometry>
      <material name="grey"/>
    </visual>
    <collision>
      <origin xyz="0.0 0.0 0.3975" rpy="0.0 0.0 0.0"/>
      <geometry>
        <cylinder radius="0.02" length="0.779"/>
      </geometry>
    </collision>
  </link>
  <gazebo reference="leg2_table_base">
    <material>Gazebo/Grey</material>
    <mu1>1000.0</mu1>
    <mu2>1000.0</mu2>
    <kp>10000000.0</kp>
    <kd>1.0</kd>
    <selfCollide>true</selfCollide>
  </gazebo>
  <joint name="table_base_to_leg2" type="fixed">
    <origin xyz="0.43 0.605 0.0" rpy="0.0 0.0 0.0"/>
    <parent link="table_base"/>
    <child link="leg2_table_base"/>
  </joint>
  <link name="leg3_table_base">
    <inertial>
      <origin xyz="0.0 0.0 0.3815" rpy="0.0 0.0 0.0"/>
      <mass value="1.0"/>
      <inertia ixx="0.1" ixy="0.0" ixz="0.0" iyy="0.1" iyz="0.0" izz="0.01"/>
    </inertial>
    <visual>
      <origin xyz="0.0 0.0 0.3815" rpy="0.0 0.0 0.0"/>
      <geometry>
        <cylinder radius="0.02" length="0.78"/>
      </geometry>
      <material name="grey"/>
    </visual>
    <collision>
      <origin xyz="0.0 0.0 0.3975" rpy="0.0 0.0 0.0"/>
      <geometry>
        <cylinder radius="0.02" length="0.779"/>
      </geometry>
    </collision>
  </link>
  <gazebo reference="leg3_table_base">
    <material>Gazebo/Grey</material>
    <mu1>1000.0</mu1>
    <mu2>1000.0</mu2>
    <kp>10000000.0</kp>
    <kd>1.0</kd>
    <selfCollide>true</selfCollide>
  </gazebo>
  <joint name="table_base_to_leg3" type="fixed">
    <origin xyz="0.43 -0.605 0.0" rpy="0.0 0.0 0.0"/>
    <parent link="table_base"/>
    <child link="leg3_table_base"/>
  </joint>
  <link name="leg4_table_base">
    <inertial>
      <origin xyz="0.0 0.0 0.3815" rpy="0.0 0.0 0.0"/>
      <mass value="1.0"/>
      <inertia ixx="0.1" ixy="0.0" ixz="0.0" iyy="0.1" iyz="0.0" izz="0.01"/>
    </inertial>
    <visual>
      <origin xyz="0.0 0.0 0.3815" rpy="0.0 0.0 0.0"/>
      <geometry>
        <cylinder radius="0.02" length="0.78"/>
      </geometry>
      <material name="grey"/>
    </visual>
    <collision>
      <origin xyz="0.0 0.0 0.3975" rpy="0.0 0.0 0.0"/>
      <geometry>
        <cylinder radius="0.02" length="0.779"/>
      </geometry>
    </collision>
  </link>
  <gazebo reference="leg4_table_base">
    <material>Gazebo/Grey</material>
    <mu1>1000.0</mu1>
    <mu2>1000.0</mu2>
    <kp>10000000.0</kp>
    <kd>1.0</kd>
    <selfCollide>true</selfCollide>
  </gazebo>
  <joint name="table_base_to_leg4" type="fixed">
    <origin xyz="-0.43 -0.605 0.0" rpy="0.0 0.0 0.0"/>
    <parent link="table_base"/>
    <child link="leg4_table_base"/>
  </joint>
  <link name="table_beam">
    <inertial>
      <origin xyz="0.0 0.0 -39.626" rpy="0.0 0.0 0.0"/>
      <mass value="1.0"/>
      <inertia ixx="0.1" ixy="0.0" ixz="0.0" iyy="0.1" iyz="0.0" izz="0.01"/>
    </inertial>
    <visual>
      <origin xyz="0.0 0.0 0.0" rpy="0.0 0.0 0.0"/>
      <geometry>
        <mesh filename="package://larcc_cell_description/meshes/minitec_45x45_1500.STL" scale="0.001 0.001 0.001"/>
      </geometry>
      <material name="grey"/>
    </visual>
    <collision>
      <origin xyz="0.0 0.0 0.0" rpy="0.0 0.0 0.0"/>
      <geometry>
        <box size="0.045 0.045 1.5"/>
      </geometry>
    </collision>
  </link>
  <joint name="table_base_to_table_beam" type="fixed">
    <origin xyz="0.305 -0.625 0.0025" rpy="1.5707963267948966 0.0 0.0"/>
    <parent link="table_base"/>
    <child link="table_beam"/>
  </joint>
  <link name="virtual_ceiling">
    <collision>
      <origin xyz="0.0 0.0 0.05" rpy="0.0 0.0 0.0"/>
      <geometry>
        <box size="5.0 5.0 0.1"/>
      </geometry>
    </collision>
    <visual>
      <origin xyz="0.0 0.0 0.05" rpy="0.0 0.0 0.0"/>
      <geometry>
        <box size="5.0 5.0 0.1"/>
      </geometry>
      <material name="red">
        <color rgba="0.5 0.0 0.0 0.0"/>
      </material>
    </visual>
  </link>
  <joint name="fixed_ceiling_joint" type="fixed">
    <origin xyz="0.0 0.0 1.8" rpy="0.0 0.0 0.0"/>
    <parent link="world"/>
    <child link="virtual_ceiling"/>
  </joint>
  <link name="charuco_small">
    <origin xyz="0 0 0" rpy="0 0 0"/>
    <visual name="pattern_1_visual">
      <origin xyz="0 0 0" rpy="0 0 0"/>
      <geometry>
        <mesh filename="package://atom_worlds/pattern/models/charuco_200x120_3x6_30_22_DICT_7X7/model.dae"/>
      </geometry>
    </visual>
  </link>
  <joint name="end_effector-charuco_small" type="fixed">
    <origin xyz="-0.06403616123716513 -0.0347038642143493 0.061710240238053174" rpy="3.1176862091264392 0.11169999443327723 1.5491231567914523"/>
    <parent link="end_effector"/>
    <child link="charuco_small"/>
  </joint>
</robot>